Traceback (most recent call last):
  File "/Users/oscargauss/Documents/CP/OFBI/2025-IWD-contest/OFBI-2025-IWD-contest/tasks/.commons/tps-scripts/internal/json_extract.py", line 13, in navigate_json
    data = data[part]
KeyError: 'subtask4'

The above exception was the direct cause of the following exception:

Traceback (most recent call last):
  File "/Users/oscargauss/Documents/CP/OFBI/2025-IWD-contest/OFBI-2025-IWD-contest/tasks/portales/scripts/internal/get_test_validators.py", line 58, in <module>
    for validator in get_test_validators(test_name=sys.argv[1], tests_dir=sys.argv[2]):
  File "/Users/oscargauss/Documents/CP/OFBI/2025-IWD-contest/OFBI-2025-IWD-contest/tasks/portales/scripts/internal/get_test_validators.py", line 46, in get_test_validators
    test_validators += navigate_json(data, 'subtasks/%s' % subtask, SUBTASKS_JSON).get('validators', [])
  File "/Users/oscargauss/Documents/CP/OFBI/2025-IWD-contest/OFBI-2025-IWD-contest/tasks/.commons/tps-scripts/internal/json_extract.py", line 23, in navigate_json
    raise Exception(
Exception: Requested key 'subtasks/subtask4' not found in 'subtasks.json'
